Workbook

Sheet README
A1: 업로드한 원본 파일을 기준으로 계산 엔진용 정규화 마스터를 만든 통합 워크북입니다.
A2: 시트 안내:
A3: 1) products_master: 제품규격표 기준 상품 규격/중량 마스터
A4: 2) boxes_master: 보유 박스 정보 기준 박스 마스터
A5: 3) packages_master: 패키지 상품 정보 기준 패키지 마스터
A6: 4) fullboxes_master: 완박스 정보 기준 완박스 마스터
A7: 적용 규칙:
A8: 1) 상품/패키지 규격은 mm → cm 로 변환
A9: 2) 상품/패키지 중량은 g → kg 로 변환
A10: 3) 박스 내경은 외경 - 1cm 로 계산
A11: 4) 보유 박스 최대허용중량은 30kg 기준으로 표준화
A13: 추가 시트 안내:
... A46: - 상품 매칭 실패 시 수동검토 없이 MATCH_FAILED로 종료

Sheet products_master
A1: 제품규격표.xlsx 기준 정규화
A3: 상품코드 | B3: 국문상품명 | C3: 가로(cm) | D3: 세로(cm) | E3: 높이(cm) | F3: 개당중량(kg) | G3: 특수상품군 | H3: 사용여부 | I3: 원본파일 | J3: 패키지상품여부 | K3: 특수우선박스코드 | L3: 특수우선입수량 | M3: 패킹정책코드 | N3: 패키지정책참조 | O3: 완박스입수량 | P3: 완박스박스코드 | Q3: 완박스박스명 | R3: 혼합완박스허용여부 | S3: 완박스혼합그룹
A4: A100210 | B4: 엑스톡스100u | C4: 7.1 | D4: 4.9 | E4: 3.7 | F4: 0.025 | H4: Y | I4: 제품규격표.xlsx
A5: A100220 | B5: 엑스톡스200u | C5: 7.1 | D5: 4.9 | E5: 3.7 | F5: 0.025 | H5: Y | I5: 제품규격표.xlsx
A6: A200135 | B6: 드메이 #4 슈퍼하드 | C6: 19.4 | D6: 7.3 | E6: 2.9 | F6: 0.05 | H6: Y | I6: 제품규격표.xlsx | M6: BOX_CAP_BX010_300_BX008_200
A7: A200140 | B7: 드메이 #3 | C7: 19.4 | D7: 7.3 | E7: 2.9 | F7: 0.05 | H7: Y | I7: 제품규격표.xlsx | M7: BOX_CAP_BX010_300_BX008_200
A8: A200145 | B8: 드메이 #2 | C8: 19.4 | D8: 7.3 | E8: 2.9 | F8: 0.05 | H8: Y | I8: 제품규격표.xlsx | M8: BOX_CAP_BX010_300_BX008_200
A9: A200150 | B9: 드메이 #1 | C9: 19.4 | D9: 7.3 | E9: 2.9 | F9: 0.05 | H9: Y | I9: 제품규격표.xlsx | M9: BOX_CAP_BX010_300_BX008_200
A10: A200210 | B10: 드메이CE3 | C10: 19.9 | D10: 6.7 | E10: 2.6 | F10: 0.044 | H10: Y | I10: 제품규격표.xlsx
A11: A200220 | B11: 드메이CE2 | C11: 19.9 | D11: 6.7 | E11: 2.6 | F11: 0.044 | H11: Y | I11: 제품규격표.xlsx
A12: A200230 | B12: 드메이CE1 | C12: 19.9 | D12: 6.7 | E12: 2.6 | F12: 0.044 | H12: Y | I12: 제품규격표.xlsx
A13: A200433 | B13: 리체스 울트라 리도(2sy C) | C13: 19.2 | D13: 7.3 | E13: 5 | F13: 0.086 | H13: Y | I13: 제품규격표.xlsx
A14: A200435 | B14: 리체스 임플란트 리도(2sy C) | C14: 19.2 | D14: 7.3 | E14: 5 | F14: 0.086 | H14: Y | I14: 제품규격표.xlsx
A15: A200436 | B15: 리체스 소프트 리도(2sy C) | C15: 19.2 | D15: 7.3 | E15: 5 | F15: 0.086 | H15: Y | I15: 제품규격표.xlsx
A16: A200437 | B16: 리체스 딥 리도(2sy C) | C16: 19.2 | D16: 7.3 | E16: 5 | F16: 0.086 | H16: Y | I16: 제품규격표.xlsx
A17: A200438 | B17: 리체스 울트라 리도(C) | C17: 19.3 | D17: 7.3 | E17: 2.8 | F17: 0.051 | H17: Y | I17: 제품규격표.xlsx | M17: BOX_CAP_BX010_300_BX008_200
A18: A200470 | B18: 리체스 PN 리도 | C18: 19.1 | D18: 7 | E18: 6 | F18: 0.085 | H18: Y | I18: 제품규격표.xlsx
A19: A200475 | B19: 리체스 PN플러스 리도 | C19: 19.1 | D19: 7 | E19: 6 | F19: 0.085 | H19: Y | I19: 제품규격표.xlsx
A20: A200610 | B20: 원필 서브큐 리도 | C20: 19 | D20: 7.1 | E20: 2.2 | F20: 0.049 | H20: Y | I20: 제품규격표.xlsx
A21: A200620 | B21: 원필 딥 리도 | C21: 19 | D21: 7.1 | E21: 2.2 | F21: 0.049 | H21: Y | I21: 제품규격표.xlsx
A22: A200630 | B22: 원필 클래식 리도 | C22: 19 | D22: 7.1 | E22: 2.2 | F22: 0.049 | H22: Y | I22: 제품규격표.xlsx
A23: A200632 | B23: 원필 비타글로우 리도 | C23: 19.2 | D23: 7.3 | E23: 5 | F23: 0.087 | H23: Y | I23: 제품규격표.xlsx
A24: A200640 | B24: 원필 서브큐 리도 CE | C24: 19.8 | D24: 6.8 | E24: 2.6 | F24: 0.041 | H24: Y | I24: 제품규격표.xlsx
A25: A200650 | B25: 원필 딥 리도 CE | C25: 19.8 | D25: 6.8 | E25: 2.6 | F25: 0.045 | H25: Y | I25: 제품규격표.xlsx
A26: A200660 | B26: 원필 클래식 리도 CE | C26: 19.8 | D26: 6.8 | E26: 2.6 | F26: 0..045 | H26: Y | I26: 제품규격표.xlsx
A27: A200670 | B27: 테오필 서브큐 리도 | C27: 19.8 | D27: 6.7 | E27: 2.6 | F27: 0.042 | H27: Y | I27: 제품규격표.xlsx
A28: A200680 | B28: 테오필 딥 리도 | C28: 19.8 | D28: 6.7 | E28: 2.6 | F28: 0.042 | H28: Y | I28: 제품규격표.xlsx
A29: A200690 | B29: 테오필 클래식 리도 | C29: 19.8 | D29: 6.7 | E29: 2.6 | F29: 0.042 | H29: Y | I29: 제품규격표.xlsx
A30: A300340 | B30: 드메이 바디 60 | C30: 9 | D30: 4.8 | E30: 4.8 | F30: 0.13 | H30: Y | I30: 제품규격표.xlsx
A31: A300345 | B31: 드메이 바디 100 | C31: 11.4 | D31: 5.2 | E31: 5.2 | F31: 0.197 | H31: Y | I31: 제품규격표.xlsx
A32: A300420 | B32: 드메이 PCL | C32: 6.5 | D32: 3.6 | E32: 3.6 | F32: 0.021 | H32: Y | I32: 제품규격표.xlsx
A33: A300510 | B33: 드메이 샤인부스터 | C33: 18.5 | D33: 9.2 | E33: 3.4 | F33: 0.143 | H33: Y | I33: 제품규격표.xlsx
A34: A300710 | B34: 리체스 B | C34: 22.5 | D34: 7.6 | E34: 3.1 | F34: 0.074 | H34: Y | I34: 제품규격표.xlsx
A35: A300715 | B35: 리체스 B (R) | C35: 23.2 | D35: 7 | E35: 3.3 | F35: 0.07 | H35: Y | I35: 제품규격표.xlsx
A36: A300800 | B36: 리체스 PCL | C36: 6.4 | D36: 3.6 | E36: 3.6 | F36: 0.021 | H36: Y | I36: 제품규격표.xlsx
A37: A300820 | B37: 리체스 PLA (COS) | C37: 6.4 | D37: 3.6 | E37: 3.6 | F37: 0.024 | H37: Y | I37: 제품규격표.xlsx
A38: A301020 | B38: 리체스 콜라필로 | C38: 19.9 | D38: 6.8 | E38: 2.7 | F38: 0.042 | H38: Y | I38: 제품규격표.xlsx
... A85: B201910 | B85: 리제니스 스파클 | C85: 19.6 | D85: 7 | E85: 7.3 | F85: 0.105 | H85: Y | I85: 제품규격표.xlsx
A86: B202010 | B86: 리플렌젠 임플란트 | C86: 19.3 | D86: 7.2 | E86: 2.8 | F86: 0.052 | H86: Y | I86: 제품규격표.xlsx | M86: BOX_CAP_BX010_300_BX008_200
A87: B202020 | B87: 리플렌젠 볼륨 | C87: 19.3 | D87: 7.2 | E87: 2.8 | F87: 0.052 | H87: Y | I87: 제품규격표.xlsx | M87: BOX_CAP_BX010_300_BX008_200
...

Sheet packages_master
A1: 패키지 상품 정보.xlsx 기준 정규화
A3: 상품코드 | B3: 국문상품명 | C3: 패키지입수량 | D3: 패키지가로(cm) | E3: 패키지세로(cm) | F3: 패키지높이(cm) | G3: 패키지중량(kg) | H3: 패키지해체정책 | I3: 사용여부 | J3: 원본파일 | K3: 엔진기본처리정책 | L3: 패키지BOM존재여부 | M3: 해체허용조건 | N3: 해체후계산단위 | O3: 잔량처리방식 | P3: 데이터검증상태 | Q3: 검증메모
A4: A100410 | B4: 독스100u | C4: 10 | D4: 18.9 | E4: 10 | F4: 7.4 | G4: 0.291 | H4: 잔량처리시만허용 | I4: Y | J4: 패키지 상품 정보.xlsx | K4: PACKAGE_AS_IS_FIRST | L4: =IF(COUNTIF(package_bom_master!$A:$A,A4)>0,"Y","N") | M4: NEED_AND_BOM_ONLY | N4: COMPONENT | O4: KEEP_PACKAGE_UNIT | P4: =IF(COUNTA(D4:G4)=4,"OK","MANUAL_REVIEW") | Q4: 기본은 패키지 상태 그대로 계산. BOM 존재 + 정책 허용 + 필요 시에만 해체.
A5: A100110 | B5: 레드톡스100u | C5: 10 | D5: 18.9 | E5: 10 | F5: 7.4 | G5: 0.291 | H5: 잔량처리시만허용 | I5: Y | J5: 패키지 상품 정보.xlsx | K5: PACKAGE_AS_IS_FIRST | L5: =IF(COUNTIF(package_bom_master!$A:$A,A5)>0,"Y","N") | M5: NEED_AND_BOM_ONLY | N5: COMPONENT | O5: KEEP_PACKAGE_UNIT | P5: =IF(COUNTA(D5:G5)=4,"OK","MANUAL_REVIEW") | Q5: 기본은 패키지 상태 그대로 계산. BOM 존재 + 정책 허용 + 필요 시에만 해체.
A6: A100120 | B6: 레드톡스200u | C6: 10 | D6: 18.9 | E6: 10 | F6: 7.4 | G6: 0.291 | H6: 잔량처리시만허용 | I6: Y | J6: 패키지 상품 정보.xlsx | K6: PACKAGE_AS_IS_FIRST | L6: =IF(COUNTIF(package_bom_master!$A:$A,A6)>0,"Y","N") | M6: NEED_AND_BOM_ONLY | N6: COMPONENT | O6: KEEP_PACKAGE_UNIT | P6: =IF(COUNTA(D6:G6)=4,"OK","MANUAL_REVIEW") | Q6: 기본은 패키지 상태 그대로 계산. BOM 존재 + 정책 허용 + 필요 시에만 해체.
A7: A100210 | B7: 엑스톡스100u | C7: 10 | D7: 18.9 | E7: 10 | F7: 7.4 | G7: 0.291 | H7: 잔량처리시만허용 | I7: Y | J7: 패키지 상품 정보.xlsx | K7: PACKAGE_AS_IS_FIRST | L7: =IF(COUNTIF(package_bom_master!$A:$A,A7)>0,"Y","N") | M7: NEED_AND_BOM_ONLY | N7: COMPONENT | O7: KEEP_PACKAGE_UNIT | P7: =IF(COUNTA(D7:G7)=4,"OK","MANUAL_REVIEW") | Q7: 기본은 패키지 상태 그대로 계산. BOM 존재 + 정책 허용 + 필요 시에만 해체.
A8: A100220 | B8: 엑스톡스200u | C8: 10 | D8: 18.9 | E8: 10 | F8: 7.4 | G8: 0.291 | H8: 잔량처리시만허용 | I8: Y | J8: 패키지 상품 정보.xlsx | K8: PACKAGE_AS_IS_FIRST | L8: =IF(COUNTIF(package_bom_master!$A:$A,A8)>0,"Y","N") | M8: NEED_AND_BOM_ONLY | N8: COMPONENT | O8: KEEP_PACKAGE_UNIT | P8: =IF(COUNTA(D8:G8)=4,"OK","MANUAL_REVIEW") | Q8: 기본은 패키지 상태 그대로 계산. BOM 존재 + 정책 허용 + 필요 시에만 해체.
A9: A100310 | B9: 원톡스 100U | C9: 10 | D9: 18.9 | E9: 10 | F9: 7.4 | G9: 0.291 | H9: 잔량처리시만허용 | I9: Y | J9: 패키지 상품 정보.xlsx | K9: PACKAGE_AS_IS_FIRST | L9: =IF(COUNTIF(package_bom_master!$A:$A,A9)>0,"Y","N") | M9: NEED_AND_BOM_ONLY | N9: COMPONENT | O9: KEEP_PACKAGE_UNIT | P9: =IF(COUNTA(D9:G9)=4,"OK","MANUAL_REVIEW") | Q9: 기본은 패키지 상태 그대로 계산. BOM 존재 + 정책 허용 + 필요 시에만 해체.
A10: A100320 | B10: 원톡스200U | C10: 10 | D10: 18.9 | E10: 10 | F10: 7.4 | G10: 0.291 | H10: 잔량처리시만허용 | I10: Y | J10: 패키지 상품 정보.xlsx | K10: PACKAGE_AS_IS_FIRST | L10: =IF(COUNTIF(package_bom_master!$A:$A,A10)>0,"Y","N") | M10: NEED_AND_BOM_ONLY | N10: COMPONENT | O10: KEEP_PACKAGE_UNIT | P10: =IF(COUNTA(D10:G10)=4,"OK","MANUAL_REVIEW") | Q10: 기본은 패키지 상태 그대로 계산. BOM 존재 + 정책 허용 + 필요 시에만 해체.
A11: A100510 | B11: 리체스 TX100 | C11: 10 | D11: 18.9 | E11: 10 | F11: 7.4 | G11: 0.291 | H11: 잔량처리시만허용 | I11: Y | J11: 패키지 상품 정보.xlsx | K11: PACKAGE_AS_IS_FIRST | L11: =IF(COUNTIF(package_bom_master!$A:$A,A11)>0,"Y","N") | M11: NEED_AND_BOM_ONLY | N11: COMPONENT | O11: KEEP_PACKAGE_UNIT | P11: =IF(COUNTA(D11:G11)=4,"OK","MANUAL_REVIEW") | Q11: 기본은 패키지 상태 그대로 계산. BOM 존재 + 정책 허용 + 필요 시에만 해체.
A12: A100520 | B12: 리체스 TX200 | C12: 10 | D12: 18.9 | E12: 10 | F12: 7.4 | G12: 0.291 | H12: 잔량처리시만허용 | I12: Y | J12: 패키지 상품 정보.xlsx | K12: PACKAGE_AS_IS_FIRST | L12: =IF(COUNTIF(package_bom_master!$A:$A,A12)>0,"Y","N") | M12: NEED_AND_BOM_ONLY | N12: COMPONENT | O12: KEEP_PACKAGE_UNIT | P12: =IF(COUNTA(D12:G12)=4,"OK","MANUAL_REVIEW") | Q12: 기본은 패키지 상태 그대로 계산. BOM 존재 + 정책 허용 + 필요 시에만 해체.
A13: B100710 | B13: 보툴렉스50u | C13: 10 | D13: 18.7 | E13: 9.3 | F13: 7.2 | G13: 0.297 | H13: 잔량처리시만허용 | I13: Y | J13: 패키지 상품 정보.xlsx | K13: PACKAGE_AS_IS_FIRST | L13: =IF(COUNTIF(package_bom_master!$A:$A,A13)>0,"Y","N") | M13: NEED_AND_BOM_ONLY | N13: COMPONENT | O13: KEEP_PACKAGE_UNIT | P13: =IF(COUNTA(D13:G13)=4,"OK","MANUAL_REVIEW") | Q13: 기본은 패키지 상태 그대로 계산. BOM 존재 + 정책 허용 + 필요 시에만 해체.
A14: B100720 | B14: 보툴렉스100u | C14: 10 | D14: 18.7 | E14: 9.3 | F14: 7.2 | G14: 0.297 | H14: 잔량처리시만허용 | I14: Y | J14: 패키지 상품 정보.xlsx | K14: PACKAGE_AS_IS_FIRST | L14: =IF(COUNTIF(package_bom_master!$A:$A,A14)>0,"Y","N") | M14: NEED_AND_BOM_ONLY | N14: COMPONENT | O14: KEEP_PACKAGE_UNIT | P14: =IF(COUNTA(D14:G14)=4,"OK","MANUAL_REVIEW") | Q14: 기본은 패키지 상태 그대로 계산. BOM 존재 + 정책 허용 + 필요 시에만 해체.
A15: B100725 | B15: 보툴렉스150u | C15: 10 | D15: 18.7 | E15: 9.3 | F15: 7.2 | G15: 0.297 | H15: 잔량처리시만허용 | I15: Y | J15: 패키지 상품 정보.xlsx | K15: PACKAGE_AS_IS_FIRST | L15: =IF(COUNTIF(package_bom_master!$A:$A,A15)>0,"Y","N") | M15: NEED_AND_BOM_ONLY | N15: COMPONENT | O15: KEEP_PACKAGE_UNIT | P15: =IF(COUNTA(D15:G15)=4,"OK","MANUAL_REVIEW") | Q15: 기본은 패키지 상태 그대로 계산. BOM 존재 + 정책 허용 + 필요 시에만 해체.
... A21: B100130 | B21: 나보타 200u | C21: 10 | D21: 25.6 | E21: 9.3 | F21: 9.3 | G21: 0.365 | H21: 잔량처리시만허용 | I21: Y | J21: 패키지 상품 정보.xlsx | K21: PACKAGE_AS_IS_FIRST | L21: =IF(COUNTIF(package_bom_master!$A:$A,A21)>0,"Y","N") | M21: NEED_AND_BOM_ONLY | N21: COMPONENT | O21: KEEP_PACKAGE_UNIT | P21: =IF(COUNTA(D21:G21)=4,"OK","MANUAL_REVIEW") | Q21: 기본은 패키지 상태 그대로 계산. BOM 존재 + 정책 허용 + 필요 시에만 해체.
A22: A300700 | B22: 리체스 카인크림 | C22: 10 | D22: 53 | E22: 23 | F22: 13 | G22: 6.9
A23: A300702 | B23: 리체스 카인플러스크림 | C23: 10 | D23: 53 | E23: 23 | F23: 13 | G23: 6.9
A24: A301210 | B24: 제이드 카인크림 | C24: 10 | D24: 53 | E24: 23 | F24: 13 | G24: 6.9
A25: A301220 | B25: 제이드 카인플러스크림 | C25: 10 | D25: 53 | E25: 23 | F25: 13 | G25: 6.9
A26: A300420 | B26: 드메이 PCL | C26: 10 | D26: 18.4 | E26: 7.4 | F26: 6.8 | G26: 0.231 | H26: 잔량처리시만허용 | I26: Y | J26: 패키지 상품 정보.xlsx | K26: PACKAGE_AS_IS_FIRST | L26: =IF(COUNTIF(package_bom_master!$A:$A,A26)>0,"Y","N") | M26: NEED_AND_BOM_ONLY | N26: COMPONENT | O26: KEEP_PACKAGE_UNIT | P26: =IF(COUNTA(D26:G26)=4,"OK","MANUAL_REVIEW") | Q26: 기본은 패키지 상태 그대로 계산. BOM 존재 + 정책 허용 + 필요 시에만 해체.
A27: A300430 | B27: 드메이 PLA | C27: 10 | D27: 18.7 | E27: 7.5 | F27: 6.7 | G27: 0.248 | H27: 잔량처리시만허용 | I27: Y | J27: 패키지 상품 정보.xlsx | K27: PACKAGE_AS_IS_FIRST | L27: =IF(COUNTIF(package_bom_master!$A:$A,A27)>0,"Y","N") | M27: NEED_AND_BOM_ONLY | N27: COMPONENT | O27: KEEP_PACKAGE_UNIT | P27: =IF(COUNTA(D27:G27)=4,"OK","MANUAL_REVIEW") | Q27: 기본은 패키지 상태 그대로 계산. BOM 존재 + 정책 허용 + 필요 시에만 해체.
A28: A300701 | B28: 리체스 카인크림 (30g) | C28: 30 | D28: 24 | E28: 18.5 | F28: 14 | G28: 1.55 | H28: 잔량처리시만허용 | I28: Y | J28: 패키지 상품 정보.xlsx | K28: PACKAGE_AS_IS_FIRST | L28: =IF(COUNTIF(package_bom_master!$A:$A,A28)>0,"Y","N") | M28: NEED_AND_BOM_ONLY | N28: COMPONENT | O28: KEEP_PACKAGE_UNIT | P28: =IF(COUNTA(D28:G28)=4,"OK","MANUAL_REVIEW") | Q28: 기본은 패키지 상태 그대로 계산. BOM 존재 + 정책 허용 + 필요 시에만 해체.
A29: A300800 | B29: 리체스 PCL | C29: 10 | D29: 18.3 | E29: 7.4 | F29: 6.7 | G29: 0.234 | H29: 잔량처리시만허용 | I29: Y | J29: 패키지 상품 정보.xlsx | K29: PACKAGE_AS_IS_FIRST | L29: =IF(COUNTIF(package_bom_master!$A:$A,A29)>0,"Y","N") | M29: NEED_AND_BOM_ONLY | N29: COMPONENT | O29: KEEP_PACKAGE_UNIT | P29: =IF(COUNTA(D29:G29)=4,"OK","MANUAL_REVIEW") | Q29: 기본은 패키지 상태 그대로 계산. BOM 존재 + 정책 허용 + 필요 시에만 해체.
A30: A300820 | B30: 리체스 PLA (COS) | C30: 10 | D30: 18.8 | E30: 7.6 | F30: 6.8 | G30: 0.268 | H30: 잔량처리시만허용 | I30: Y | J30: 패키지 상품 정보.xlsx | K30: PACKAGE_AS_IS_FIRST | L30: =IF(COUNTIF(package_bom_master!$A:$A,A30)>0,"Y","N") | M30: NEED_AND_BOM_ONLY | N30: COMPONENT | O30: KEEP_PACKAGE_UNIT | P30: =IF(COUNTA(D30:G30)=4,"OK","MANUAL_REVIEW") | Q30: 기본은 패키지 상태 그대로 계산. BOM 존재 + 정책 허용 + 필요 시에만 해체.
A31: B100125 | B31: 나보타150u | C31: 10 | D31: 25.6 | E31: 9.3 | F31: 9.3 | G31: 0.367 | H31: 잔량처리시만허용 | I31: Y | J31: 패키지 상품 정보.xlsx | K31: PACKAGE_AS_IS_FIRST | L31: =IF(COUNTIF(package_bom_master!$A:$A,A31)>0,"Y","N") | M31: NEED_AND_BOM_ONLY | N31: COMPONENT | O31: KEEP_PACKAGE_UNIT | P31: =IF(COUNTA(D31:G31)=4,"OK","MANUAL_REVIEW") | Q31: 기본은 패키지 상태 그대로 계산. BOM 존재 + 정책 허용 + 필요 시에만 해체.
A32: B100260 | B32: 뉴럭스100u | C32: 10 | D32: 16.8 | E32: 14.3 | F32: 5.5 | G32: 0.323 | H32: 잔량처리시만허용 | I32: Y | J32: 패키지 상품 정보.xlsx | K32: PACKAGE_AS_IS_FIRST | L32: =IF(COUNTIF(package_bom_master!$A:$A,A32)>0,"Y","N") | M32: NEED_AND_BOM_ONLY | N32: COMPONENT | O32: KEEP_PACKAGE_UNIT | P32: =IF(COUNTA(D32:G32)=4,"OK","MANUAL_REVIEW") | Q32: 기본은 패키지 상태 그대로 계산. BOM 존재 + 정책 허용 + 필요 시에만 해체.
A33: B100410 | B33: 리엔톡스100u | C33: 100 | D33: 28 | E33: 23.3 | F33: 18.9 | G33: 2.791 | H33: 잔량처리시만허용 | I33: Y | J33: 패키지 상품 정보.xlsx | K33: PACKAGE_AS_IS_FIRST | L33: =IF(COUNTIF(package_bom_master!$A:$A,A33)>0,"Y","N") | M33: NEED_AND_BOM_ONLY | N33: COMPONENT | O33: KEEP_PACKAGE_UNIT | P33: =IF(COUNTA(D33:G33)=4,"OK","MANUAL_REVIEW") | Q33: 기본은 패키지 상태 그대로 계산. BOM 존재 + 정책 허용 + 필요 시에만 해체.
A34: B100420 | B34: 리엔톡스200u | C34: 100 | D34: 28 | E34: 23.3 | F34: 18.9 | G34: 2.791 | H34: 잔량처리시만허용 | I34: Y | J34: 패키지 상품 정보.xlsx | K34: PACKAGE_AS_IS_FIRST | L34: =IF(COUNTIF(package_bom_master!$A:$A,A34)>0,"Y","N") | M34: NEED_AND_BOM_ONLY | N34: COMPONENT | O34: KEEP_PACKAGE_UNIT | P34: =IF(COUNTA(D34:G34)=4,"OK","MANUAL_REVIEW") | Q34: 기본은 패키지 상태 그대로 계산. BOM 존재 + 정책 허용 + 필요 시에만 해체.
A35: B100610 | B35: 메디톡신100u | C35: 10 | D35: 16.6 | E35: 14.5 | F35: 5.6 | G35: 0.323 | H35: 잔량처리시만허용 | I35: Y | J35: 패키지 상품 정보.xlsx | K35: PACKAGE_AS_IS_FIRST | L35: =IF(COUNTIF(package_bom_master!$A:$A,A35)>0,"Y","N") | M35: NEED_AND_BOM_ONLY | N35: COMPONENT | O35: KEEP_PACKAGE_UNIT | P35: =IF(COUNTA(D35:G35)=4,"OK","MANUAL_REVIEW") | Q35: 기본은 패키지 상태 그대로 계산. BOM 존재 + 정책 허용 + 필요 시에만 해체.
A36: B100630 | B36: 메디톡신200u | C36: 10 | D36: 16.6 | E36: 14.5 | F36: 5.6 | G36: 0.329 | H36: 잔량처리시만허용 | I36: Y | J36: 패키지 상품 정보.xlsx | K36: PACKAGE_AS_IS_FIRST | L36: =IF(COUNTIF(package_bom_master!$A:$A,A36)>0,"Y","N") | M36: NEED_AND_BOM_ONLY | N36: COMPONENT | O36: KEEP_PACKAGE_UNIT | P36: =IF(COUNTA(D36:G36)=4,"OK","MANUAL_REVIEW") | Q36: 기본은 패키지 상태 그대로 계산. BOM 존재 + 정책 허용 + 필요 시에만 해체.
A37: B101110 | B37: 이노톡스50u | C37: 10 | D37: 16.7 | E37: 14.5 | F37: 5.5 | G37: 0.284 | H37: 잔량처리시만허용 | I37: Y | J37: 패키지 상품 정보.xlsx | K37: PACKAGE_AS_IS_FIRST | L37: =IF(COUNTIF(package_bom_master!$A:$A,A37)>0,"Y","N") | M37: NEED_AND_BOM_ONLY | N37: COMPONENT | O37: KEEP_PACKAGE_UNIT | P37: =IF(COUNTA(D37:G37)=4,"OK","MANUAL_REVIEW") | Q37: 기본은 패키지 상태 그대로 계산. BOM 존재 + 정책 허용 + 필요 시에만 해체.
... A46: B309230 | B46: 트리암시놀론주40mg | C46: 10 | D46: 39.8 | E46: 9.5 | F46: 9 | G46: 2.152 | H46: 잔량처리시만허용 | I46: Y | J46: 패키지 상품 정보.xlsx | K46: PACKAGE_AS_IS_FIRST | L46: =IF(COUNTIF(package_bom_master!$A:$A,A46)>0,"Y","N") | M46: NEED_AND_BOM_ONLY | N46: COMPONENT | O46: KEEP_PACKAGE_UNIT | P46: =IF(COUNTA(D46:G46)=4,"OK","MANUAL_REVIEW") | Q46: 기본은 패키지 상태 그대로 계산. BOM 존재 + 정책 허용 + 필요 시에만 해체.

Sheet boxes_master
A1: 보유 박스 정보.xlsx 기준 정규화
A3: 박스코드 | B3: 박스명 | C3: 원본박스명 | D3: 외경가로(cm) | E3: 외경세로(cm) | F3: 외경높이(cm) | G3: 내경가로(cm) | H3: 내경세로(cm) | I3: 내경높이(cm) | J3: 박스중량(kg) | K3: 최대허용중량(kg) | L3: active | M3: 원본파일 | N3: 박스정렬우선순위
A4: BX001 | B4: 1호 | C4: 1호 | D4: 22 | E4: 19 | F4: 9 | G4: 21 | H4: 18 | I4: 8 | J4: 0.12 | K4: 30 | L4: Y | M4: 보유 박스 정보.xlsx | N4: 10
A5: BX002 | B5: 2호 | C5: 2호 | D5: 27 | E5: 18 | F5: 15 | G5: 26 | H5: 17 | I5: 14 | J5: 0.18 | K5: 30 | L5: Y | M5: 보유 박스 정보.xlsx | N5: 9
A6: BX003 | B6: 34.5x25.5x10.5 | C6: 명칭없음 | D6: 34.5 | E6: 25.5 | F6: 10.5 | G6: 33.5 | H6: 24.5 | I6: 9.5 | J6: 0.22 | K6: 30 | L6: Y | M6: 보유 박스 정보.xlsx | N6: 8
A7: BX004 | B7: 3호 | C7: 3호 | D7: 34 | E7: 25 | F7: 21 | G7: 33 | H7: 24 | I7: 20 | J7: 0.5 | K7: 30 | L7: Y | M7: 보유 박스 정보.xlsx | N7: 7
A8: BX005 | B8: 4호 | C8: 4호 | D8: 41 | E8: 31 | F8: 28 | G8: 40 | H8: 30 | I8: 27 | J8: 0.72 | K8: 30 | L8: Y | M8: 보유 박스 정보.xlsx | N8: 6
A9: BX006 | B9: 5호 | C9: 5호 | D9: 48 | E9: 38 | F9: 34 | G9: 47 | H9: 37 | I9: 33 | J9: 1.26 | K9: 30 | L9: Y | M9: 보유 박스 정보.xlsx | N9: 5
A10: BX007 | B10: 6호 | C10: 6호 | D10: 52 | E10: 48 | F10: 40 | G10: 51.5 | H10: 47.5 | I10: 39.5 | J10: 1.52 | K10: 30 | L10: Y | M10: 보유 박스 정보.xlsx | N10: 3
A11: BX008 | B11: 60x40x40 | C11: 명칭없음 | D11: 60 | E11: 40 | F11: 40 | G11: 59 | H11: 39 | I11: 39 | J11: 1.62 | K11: 30 | L11: Y | M11: 보유 박스 정보.xlsx | N11: 4
A12: BX009 | B12: 65x45x40 | C12: 명칭없음 | D12: 65 | E12: 45 | F12: 40 | G12: 64 | H12: 44 | I12: 39 | J12: 1.44 | K12: 30 | L12: Y | M12: 보유 박스 정보.xlsx | N12: 2
A13: BX010 | B13: 72x48x40 | C13: 명칭없음 | D13: 72 | E13: 48 | F13: 40 | G13: 71 | H13: 47 | I13: 39 | J13: 2.2 | K13: 30 | L13: Y | M13: 보유 박스 정보.xlsx | N13: 1

Sheet package_bom_master
A1: 패키지 해체(BOM) 마스터 - 현재 원본 데이터 없음, 추후 확장용
A3: 패키지상품코드 | B3: 패키지국문상품명 | C3: 구성품상품코드 | D3: 구성품국문상품명 | E3: 구성품수량 | F3: 해체적용조건 | G3: 사용여부 | H3: 원본파일 | I3: 데이터검증상태 | J3: 검증메모
J4: 현재 원본 파일에 BOM 데이터 없음. 해체 계산 필요 시 이 시트 보강 필요.

Sheet fullboxes_master
A1: 완박스 정보.xlsx 기준 정규화
A3: 상품코드 | B3: 국문상품명 | C3: 완박스입수량 | D3: 완박스가로(cm) | E3: 완박스세로(cm) | F3: 완박스높이(cm) | G3: 완박스중량(kg) | H3: 우선순위 | I3: 사용여부 | J3: 원본파일 | K3: 완박스카톤코드 | L3: 엔진해석정책 | M3: 출고단위구분 | N3: 표준박스매핑여부 | O3: 표준박스코드 | P3: 잔량처리방식 | Q3: 데이터검증상태 | R3: 검증메모 | S3: 완박스박스코드 | T3: 완박스박스명 | U3: 혼합완박스허용여부 | V3: 완박스혼합그룹
A4: B200204 | B4: 뉴라미스 딥 노리도 | C4: 100 | D4: 37 | E4: 37 | F4: 32 | G4: 4.7 | H4: 1 | I4: Y | J4: 완박스 정보.xlsx | K4: FBX005 | L4: OWN_CARTON | M4: FULLBOX_CARTON | N4: N | P4: REMAINDER_TO_REPACK | Q4: OK | R4: 완박스를 표준박스로 매핑하지 않고 자체 출고 카톤으로 사용 | S4: FBX005 | T4: 완박스 37x37x32 | U4: Y | V4: FBG005
A5: B200240 | B5: 뉴라미스 딥 노리도 (수출용) | C5: 100 | D5: 37 | E5: 37 | F5: 32 | G5: 4.7 | H5: 1 | I5: Y | J5: 완박스 정보.xlsx | K5: FBX005 | L5: OWN_CARTON | M5: FULLBOX_CARTON | N5: N | P5: REMAINDER_TO_REPACK | Q5: OK | R5: 완박스를 표준박스로 매핑하지 않고 자체 출고 카톤으로 사용 | S5: FBX005 | T5: 완박스 37x37x32 | U5: Y | V5: FBG005
A6: B200201 | B6: 뉴라미스 딥 리도 | C6: 100 | D6: 38 | E6: 37 | F6: 25.5 | G6: 4.5 | H6: 1 | I6: Y | J6: 완박스 정보.xlsx | K6: FBX006 | L6: OWN_CARTON | M6: FULLBOX_CARTON | N6: N | P6: REMAINDER_TO_REPACK | Q6: OK | R6: 완박스를 표준박스로 매핑하지 않고 자체 출고 카톤으로 사용 | S6: FBX006 | T6: 완박스 38x37x25.5 | U6: Y | V6: FBG006
A7: B200220 | B7: 뉴라미스 딥 리도(수출용) | C7: 100 | D7: 38 | E7: 37 | F7: 25.5 | G7: 4.5 | H7: 1 | I7: Y | J7: 완박스 정보.xlsx | K7: FBX006 | L7: OWN_CARTON | M7: FULLBOX_CARTON | N7: N | P7: REMAINDER_TO_REPACK | Q7: OK | R7: 완박스를 표준박스로 매핑하지 않고 자체 출고 카톤으로 사용 | S7: FBX006 | T7: 완박스 38x37x25.5 | U7: Y | V7: FBG006
A8: B200203 | B8: 뉴라미스 라이트 리도 | C8: 100 | D8: 37 | E8: 37 | F8: 32 | G8: 4.7 | H8: 1 | I8: Y | J8: 완박스 정보.xlsx | K8: FBX005 | L8: OWN_CARTON | M8: FULLBOX_CARTON | N8: N | P8: REMAINDER_TO_REPACK | Q8: OK | R8: 완박스를 표준박스로 매핑하지 않고 자체 출고 카톤으로 사용 | S8: FBX005 | T8: 완박스 37x37x32 | U8: Y | V8: FBG005
A9: B200234 | B9: 뉴라미스 라이트 리도(수출용) | C9: 100 | D9: 37 | E9: 37 | F9: 32 | G9: 4.7 | H9: 1 | I9: Y | J9: 완박스 정보.xlsx | K9: FBX005 | L9: OWN_CARTON | M9: FULLBOX_CARTON | N9: N | P9: REMAINDER_TO_REPACK | Q9: OK | R9: 완박스를 표준박스로 매핑하지 않고 자체 출고 카톤으로 사용 | S9: FBX005 | T9: 완박스 37x37x32 | U9: Y | V9: FBG005
A10: B200202 | B10: 뉴라미스 리도(실버) | C10: 100 | D10: 38 | E10: 37 | F10: 25.5 | G10: 4.5 | H10: 1 | I10: Y | J10: 완박스 정보.xlsx | K10: FBX006 | L10: OWN_CARTON | M10: FULLBOX_CARTON | N10: N | P10: REMAINDER_TO_REPACK | Q10: OK | R10: 완박스를 표준박스로 매핑하지 않고 자체 출고 카톤으로 사용 | S10: FBX006 | T10: 완박스 38x37x25.5 | U10: Y | V10: FBG006
A11: B200230 | B11: 뉴라미스 리도(실버)(수출용) | C11: 100 | D11: 38 | E11: 37 | F11: 25.5 | G11: 4.5 | H11: 1 | I11: Y | J11: 완박스 정보.xlsx | K11: FBX006 | L11: OWN_CARTON | M11: FULLBOX_CARTON | N11: N | P11: REMAINDER_TO_REPACK | Q11: OK | R11: 완박스를 표준박스로 매핑하지 않고 자체 출고 카톤으로 사용 | S11: FBX006 | T11: 완박스 38x37x25.5 | U11: Y | V11: FBG006
A12: B200200 | B12: 뉴라미스 볼륨 리도 | C12: 100 | D12: 38 | E12: 37 | F12: 25.5 | G12: 4.5 | H12: 1 | I12: Y | J12: 완박스 정보.xlsx | K12: FBX006 | L12: OWN_CARTON | M12: FULLBOX_CARTON | N12: N | P12: REMAINDER_TO_REPACK | Q12: OK | R12: 완박스를 표준박스로 매핑하지 않고 자체 출고 카톤으로 사용 | S12: FBX006 | T12: 완박스 38x37x25.5 | U12: Y | V12: FBG006
A13: B200210 | B13: 뉴라미스 볼륨 리도(수출용) | C13: 100 | D13: 38 | E13: 37 | F13: 25.5 | G13: 4.5 | H13: 1 | I13: Y | J13: 완박스 정보.xlsx | K13: FBX006 | L13: OWN_CARTON | M13: FULLBOX_CARTON | N13: N | P13: REMAINDER_TO_REPACK | Q13: OK | R13: 완박스를 표준박스로 매핑하지 않고 자체 출고 카톤으로 사용 | S13: FBX006 | T13: 완박스 38x37x25.5 | U13: Y | V13: FBG006
A14: B300820 | B14: 닥터 리포 플러스 | C14: 60 | D14: 53 | E14: 37 | F14: 34 | G14: 23.4 | H14: 1 | I14: Y | J14: 완박스 정보.xlsx | K14: FBX067 | L14: OWN_CARTON | M14: FULLBOX_CARTON | N14: N | P14: REMAINDER_TO_REPACK | Q14: OK | R14: 완박스를 표준박스로 매핑하지 않고 자체 출고 카톤으로 사용 | S14: FBX067 | T14: 완박스 53x37x34 | U14: Y | V14: FBG091
A15: B200620 | B15: 더마렉스 딥 플러스 | C15: 200 | D15: 60 | E15: 42 | F15: 42 | G15: 10.5 | H15: 1 | I15: Y | J15: 완박스 정보.xlsx | K15: FBX088 | L15: OWN_CARTON | M15: FULLBOX_CARTON | N15: N | P15: REMAINDER_TO_REPACK | Q15: OK | R15: 완박스를 표준박스로 매핑하지 않고 자체 출고 카톤으로 사용 | S15: FBX088 | T15: 완박스 60x42x42 | U15: Y | V15: FBG048
... A233: B206910 | B233: 히아필리아 미담 프라임 플러스 | C233: 100 | D233: 39.5 | E233: 37 | F233: 24 | G233: 4.64 | H233: 1 | I233: Y | J233: 완박스 정보.xlsx | K233: FBX120 | L233: OWN_CARTON | M233: FULLBOX_CARTON | N233: N | P233: REMAINDER_TO_REPACK | Q233: OK | R233: 완박스를 표준박스로 매핑하지 않고 자체 출고 카톤으로 사용 | S233: FBX120 | T233: 완박스 39.5x37x24 | U233: Y | V233: FBG006

Sheet fullbox_cartons_master
A1: fullboxes_master에서 파생된 완박스 출고 카톤 마스터
A3: 완박스카톤코드 | B3: 외경가로(cm) | C3: 외경세로(cm) | D3: 외경높이(cm) | E3: 카톤총중량(kg) | F3: 연결SKU행수 | G3: 연결상품코드수 | H3: 엔진해석정책 | I3: 표준박스매핑여부 | J3: 원본시트 | K3: 비고
A4: FBX001 | B4: 32 | C4: 31 | D4: 20 | E4: 8.3 | F4: 2 | G4: 2 | H4: OWN_CARTON | I4: N | J4: fullboxes_master | K4: 완박스는 자체 카톤 규격으로 출고 처리
A5: FBX002 | B5: 34 | C5: 31 | D5: 16 | E5: 3.6 | F5: 1 | G5: 1 | H5: OWN_CARTON | I5: N | J5: fullboxes_master | K5: 완박스는 자체 카톤 규격으로 출고 처리
A6: FBX003 | B6: 34 | C6: 31 | D6: 16 | E6: 3.74 | F6: 2 | G6: 2 | H6: OWN_CARTON | I6: N | J6: fullboxes_master | K6: 완박스는 자체 카톤 규격으로 출고 처리
A7: FBX004 | B7: 34 | C7: 31 | D7: 16 | E7: 3.9 | F7: 2 | G7: 2 | H7: OWN_CARTON | I7: N | J7: fullboxes_master | K7: 완박스는 자체 카톤 규격으로 출고 처리
A8: FBX005 | B8: 37 | C8: 37 | D8: 32 | E8: 4.7 | F8: 4 | G8: 4 | H8: OWN_CARTON | I8: N | J8: fullboxes_master | K8: 완박스는 자체 카톤 규격으로 출고 처리
A9: FBX006 | B9: 38 | C9: 37 | D9: 25.5 | E9: 4.5 | F9: 3 | G9: 3 | H9: OWN_CARTON | I9: N | J9: fullboxes_master | K9: 완박스는 자체 카톤 규격으로 출고 처리
A10: FBX007 | B10: 39 | C10: 25 | D10: 22 | E10: 2.55 | F10: 1 | G10: 1 | H10: OWN_CARTON | I10: N | J10: fullboxes_master | K10: 완박스는 자체 카톤 규격으로 출고 처리
A11: FBX008 | B11: 39 | C11: 25 | D11: 22 | E11: 7 | F11: 1 | G11: 1 | H11: OWN_CARTON | I11: N | J11: fullboxes_master | K11: 완박스는 자체 카톤 규격으로 출고 처리
A12: FBX009 | B12: 39 | C12: 36.5 | D12: 24.5 | E12: 4.8 | F12: 1 | G12: 1 | H12: OWN_CARTON | I12: N | J12: fullboxes_master | K12: 완박스는 자체 카톤 규격으로 출고 처리
A13: FBX010 | B13: 39.5 | C13: 22.5 | D13: 39.5 | E13: 6.5 | F13: 6 | G13: 6 | H13: OWN_CARTON | I13: N | J13: fullboxes_master | K13: 완박스는 자체 카톤 규격으로 출고 처리
A14: FBX011 | B14: 39.5 | C14: 22.5 | D14: 39.5 | E14: 6.6 | F14: 2 | G14: 2 | H14: OWN_CARTON | I14: N | J14: fullboxes_master | K14: 완박스는 자체 카톤 규격으로 출고 처리
A15: FBX012 | B15: 39.5 | C15: 22.5 | D15: 39.5 | E15: 6.7 | F15: 1 | G15: 1 | H15: OWN_CARTON | I15: N | J15: fullboxes_master | K15: 완박스는 자체 카톤 규격으로 출고 처리
... A95: FBX092 | B95: 72 | C95: 46 | D95: 17 | E95: 15.95 | F95: 1 | G95: 1 | H95: OWN_CARTON | I95: N | J95: fullboxes_master | K95: 완박스는 자체 카톤 규격으로 출고 처리
A97: 수동검토 필요 행 | B97: 97

Sheet engine_flow
A1: 패킹 엔진 처리 순서(flow) 확정
A3: step_no | B3: phase | C3: 입력/조건 | D3: 참조시트 | E3: 핵심 로직 | F3: 산출물 | G3: 중단/예외조건 | H3: 비고
A4: 1 | B4: INPUT_NORMALIZE | C4: 주문라인(product_code, qty) | D4: products_master | E4: 상품코드/상품명 정규화 및 active 확인 | F4: normalized_order_lines | G4: 상품 미존재 또는 inactive | H4: 입력 표준화
A5: 2 | B5: TYPE_DETECT | C5: 정규화된 주문라인 | D5: products_master, packages_master | E5: 상품 유형 판별: NORMAL / SPECIAL_300 / PACKAGE_SEALED | F5: typed_order_lines | G5: 유형 판별 실패 | H5: 패키지 여부는 packages_master 기준
A6: 3 | B6: MASTER_VALIDATE | C6: typed_order_lines | D6: boxes_master, fullboxes_master, packages_master | E6: 계산에 필요한 규격/중량/정책 존재 여부 확인 | F6: validated_order_lines | G6: 필수 규격/중량 누락 | H6: 누락 시 MANUAL_REVIEW
A7: 4 | B7: FULLBOX_ALLOCATE | C7: validated_order_lines | D7: fullboxes_master, fullbox_cartons_master | E7: 완박스 가능 SKU는 완박스부터 우선 배정 | F7: fullbox_allocations | G7: 완박스 규격 누락 | H7: 완박스는 OWN_CARTON
A8: 5 | B8: PACKAGE_POLICY_APPLY | C8: 잔여 package sku | D8: packages_master, package_bom_master | E8: 기본은 패키지 상태 그대로 계산. 해체는 BOM 존재 + 정책 허용 + 실제 필요 시만 허용 | F8: package_allocations | G8: BOM 필요한데 부재 | H8: 기본 정책 PACKAGE_AS_IS_FIRST
A9: 6 | B9: SPECIAL_POLICY_APPLY | C9: 잔여 special sku | D9: products_master, rules_master | E9: 특수군은 BX010(72x48x40)에 300개 우선 배정 시도 | F9: special_allocations | G9: 박스/중량 제약 불가 | H9: ELASTY/CELLOZOME/REPLENGEN/RICHESSE_C/DEMEI
A10: 7 | B10: NORMAL_PACKING | C10: 잔여 normal sku | D10: boxes_master, products_master, rules_master | E10: 박스 수 최소화 우선 + 같은 상품 우선 + 동률이면 큰 박스 우선 | F10: normal_allocations | G10: 적합 박스 없음 | H10: 내경 = 외경 - 1cm
A11: 8 | B11: WEIGHT_CHECK | C11: 모든 allocation | D11: rules_master | E11: 30kg 초과 여부 확인 및 초과안 재배치 | F11: weight_valid_allocations | G11: 대체 배치 실패 | H11: max 30kg
A12: 9 | B12: SPACE_CHECK | C12: 확정 allocation | D12: rules_master | E12: 상단 유효공간 계산. 2cm 이상이면 제단 안내/가능높이 산출 | F12: space_checked_allocations | G12: - | H12: trim notice 생성
A13: 10 | B13: MERGE_RESULT | C13: fullbox+package+special+normal | D13: engine internal | E13: 모든 allocation을 carton 기준으로 병합/정렬 | F13: merged_cartons | G13: - | H13: carton_seq 부여
A14: 11 | B14: BUILD_PACKING_LIST | C14: merged_cartons | D14: output_schema | E14: 템플릿 형식 패킹리스트 행 생성 | F14: packing_list_rows | G14: 필수 출력필드 누락 | H14: 출력 포맷 고정
A15: 12 | B15: SUMMARY | C15: packing_list_rows | D15: output_schema | E15: 총 박스수/총수량/검토대상 요약 생성 | F15: packing_list_summary | G15: - | H15: 최종 사용자 출력

Sheet input_json_schema
A1: 입력 JSON 스키마 확정
A3: json_path | B3: 필드명(ko) | C3: level | D3: type | E3: required | F3: enum/example | G3: validation_rule | H3: 설명
A4: $.request_version | B4: 요청버전 | C4: job | D4: text | E4: Y | F4: v1 | G4: 지원 스키마 버전과 일치 | H4: 요청 JSON 버전
A5: $.job_id | B5: 작업ID | C5: job | D5: text | E5: N | F5: PK-20260310-0001 | G5: 미입력 시 엔진 자동 생성 | H5: 요청 식별자
A6: $.packing_mode | B6: 출고방법 | C6: job | D6: text | E6: Y | F6: AUTO / REPACK / FULLBOX | G6: enum | H6: 계산 모드. AUTO면 엔진이 완박스→재포장 순으로 판단
A7: $.packing_list_required | B7: 패킹리스트필요 | C7: job | D7: boolean | E7: Y | F7: true / false | G7: bool | H7: 출력 형식 제어
A8: $.output_language | B8: 출력언어 | C8: job | D8: text | E8: N | F8: ko / en / ru | G8: 미입력 시 ko | H8: 안내 문구 언어
A9: $.order_lines | B9: 주문라인목록 | C9: array | D9: array | E9: Y | F9: [...] | G9: 최소 1행 | H9: 계산 대상 주문 라인 배열
A10: $.order_lines[].order_line_no | B10: 주문행번호 | C10: line | D10: number | E10: Y | F10: 1 | G10: 양의 정수 | H10: 입력 순번 유지용
A11: $.order_lines[].product_code | B11: 상품코드 | C11: line | D11: text | E11: N | F11: P000123 | G11: product_code 또는 product_name 중 1개 이상 필수 | H11: 상품 식별값
A12: $.order_lines[].product_name | B12: 상품명 | C12: line | D12: text | E12: N | F12: 리체스 딥 리도(c) | G12: product_code 또는 product_name 중 1개 이상 필수 | H12: 상품 식별값
A13: $.order_lines[].qty | B13: 수량 | C13: line | D13: number | E13: Y | F13: 225 | G13: 0 초과 정수 | H13: 주문 수량
A14: $.options.allow_package_unseal | B14: 패키지해체허용 | C14: option | D14: boolean | E14: N | F14: false | G14: 기본 false | H14: true 여도 BOM 존재 + 정책 허용 시만 해체 가능
... A18: $.options.output_detail_level | B18: 출력상세수준 | C18: option | D18: text | E18: N | F18: SUMMARY / FULL | G18: 기본 FULL | H18: 결과 JSON 상세 정도

Sheet output_schema
A1: 패킹리스트 출력 스키마 확정
A3: field_key | B3: 필드명(ko) | C3: level | D3: type | E3: required | F3: source | G3: 생성 규칙 | H3: 설명
A4: job_id | B4: 작업ID | C4: job | D4: text | E4: Y | F4: engine runtime | G4: 실행 단위별 고유값 | H4: 1회 계산 요청 식별자
A5: order_line_no | B5: 주문행번호 | C5: line | D5: number | E5: Y | F5: input order | G5: 입력 행 순번 유지 | H5: 원주문 라인 추적
A6: input_product_code | B6: 입력상품코드 | C6: line | D6: text | E6: Y | F6: input order | G6: 원입력값 | H6: 주문 기준 상품코드
A7: input_product_name | B7: 입력상품명 | C7: line | D7: text | E7: N | F7: input order | G7: 원입력값 | H7: 주문 기준 상품명
A8: normalized_product_code | B8: 정규화상품코드 | C8: line | D8: text | E8: Y | F8: products_master | G8: 정규화 결과 | H8: 계산 기준 상품코드
A9: product_type | B9: 상품유형 | C9: line | D9: text | E9: Y | F9: products_master/packages_master | G9: NORMAL/SPECIAL_300/PACKAGE_SEALED/FULLBOX_CARTON | H9: 계산 분기용
A10: carton_seq | B10: 카톤순번 | C10: carton | D10: number | E10: Y | F10: engine runtime | G10: 최종 카톤 정렬 후 순번 부여 | H10: 출력용 박스 번호
A11: carton_type | B11: 카톤유형 | C11: carton | D11: text | E11: Y | F11: engine runtime | G11: STANDARD_BOX/FULLBOX_CARTON/PACKAGE_UNIT | H11: 카톤 해석 유형
A12: carton_code | B12: 카톤코드 | C12: carton | D12: text | E12: Y | F12: boxes_master/fullbox_cartons_master/packages_master | G12: 참조 마스터 코드 | H12: 사용 카톤 식별자
A13: carton_name | B13: 카톤명 | C13: carton | D13: text | E13: N | F13: boxes_master/fullbox_cartons_master/packages_master | G13: 참조 이름 | H13: 사용 카톤 표시명
A14: outer_length_cm | B14: 외경가로(cm) | C14: carton | D14: number | E14: Y | F14: carton master | G14: 선택 카톤 외경 | H14: 출력 규격
... A27: packing_note | B27: 패킹메모 | C27: carton | D27: text | E27: N | F27: engine runtime | G27: 사용자 안내 문구 | H27: 출력 템플릿 표기용

Sheet output_json_schema
A1: 출력 JSON 스키마 확정
A3: json_path | B3: 필드명(ko) | C3: level | D3: type | E3: required | F3: enum/example | G3: validation_rule | H3: 설명
A4: $.response_version | B4: 응답버전 | C4: job | D4: text | E4: Y | F4: v1 | G4: 고정 | H4: 응답 JSON 버전
A5: $.job_id | B5: 작업ID | C5: job | D5: text | E5: Y | F5: PK-20260310-0001 | G5: request echo | H5: 요청 식별자
A6: $.engine_version | B6: 엔진버전 | C6: job | D6: text | E6: Y | F6: packing-engine-v1 | G6: runtime | H6: 엔진 배포 버전
A7: $.request_echo.packing_mode | B7: 요청출고방법 | C7: job | D7: text | E7: Y | F7: AUTO | G7: request echo | H7: 원요청 추적
A8: $.request_echo.packing_list_required | B8: 요청패킹리스트필요 | C8: job | D8: boolean | E8: Y | F8: false | G8: request echo | H8: 원요청 추적
A9: $.summary.total_input_lines | B9: 총입력행수 | C9: summary | D9: number | E9: Y | F9: 3 | G9: sum | H9: 입력 라인 수
A10: $.summary.total_input_qty | B10: 총입력수량 | C10: summary | D10: number | E10: Y | F10: 325 | G10: sum | H10: 총 주문 수량
A11: $.summary.total_cartons | B11: 총카톤수 | C11: summary | D11: number | E11: Y | F11: 2 | G11: count | H11: 최종 출고 카톤 수
A12: $.summary.manual_review_yn | B12: 수동검토여부 | C12: summary | D12: text | E12: Y | F12: N | G12: Y/N | H12: 예외 존재 여부
A13: $.cartons | B13: 카톤목록 | C13: array | D13: array | E13: Y | F13: [...] | G13: 0건 가능 | H13: 최종 출고 카톤 배열
A14: $.cartons[].carton_seq | B14: 카톤순번 | C14: carton | D14: number | E14: Y | F14: 1 | G14: 1부터 순차 | H14: 출력용 카톤 번호
... A38: $.packing_notes | B38: 패킹메모목록 | C38: array | D38: array | E38: N | F38: [...] | G38: 없으면 빈 배열 | H38: 사용자 안내 문구

Sheet json_examples
A1: 입력/출력 JSON 예시
A3: request_example | E3: response_example
A4: { "request_version": "v1", "job_id": "PK-20260310-0001", "packing_mode": "REPACK", "packing_list_required": false, "output_language": "ko", "order_lines": [ { "order_line_no": 1, "product_name": "비에녹스 200u", "qty": 75 }, { "order_line_no": 2, "product_name": "리체스 딥 리도(c)", "qty": 225 }, { "order_line_no": 3, "product_name": "엘라스티 D 리도", "qty": 25 } ], "options": { "allow_package_unseal": false, "allow_manual_review": true, "prefer_same_sku_carton": true, "max_box_weight_kg": 30, "output_detail_level": "FULL" } } | E4: { "response_version": "v1", "job_id": "PK-20260310-0001", "engine_version": "packing-engine-v1", "request_echo": { "packing_mode": "REPACK", "packing_list_required": false }, "summary": { "total_input_lines": 3, "total_input_qty": 325, "total_cartons": 2, "manual_review_yn": "N" }, "cartons": [ { "carton_seq": 1, "carton_type": "STANDARD_BOX", "carton_code": "BX010", "carton_name": "72 x 48 x 40", "outer_length_cm": 72, "outer_width_cm": 48, "outer_height_cm": 40, "gross_weight_kg": 12.6, "empty_top_space_cm": 3.0, "trim_notice_yn": "Y", "trim_possible_height_cm": 37, "items": [ { "order_line_no": 2, "normalized_product_code": "AUTO_MATCH", "product_name": "리체스 딥 리도(c)", "product_type": "SPECIAL_300", "packed_qty": 225, "fullbox_applied_yn": "N", "package_kept_yn": "N", "special_rule_applied_yn": "Y" }, { "order_line_no": 3, "normalized_product_code": "AUTO_MATCH", "product_name": "엘라스티 D 리도", "product_type": "SPECIAL_300", "packed_qty": 25, "fullbox_applied_yn": "N", "package_kept_yn": "N", "special_rule_applied_yn": "Y" } ] }, { "carton_seq": 2, "carton_type": "STANDARD_BOX", "carton_code": "BX005", "carton_name": "40 x 30 x 25", "outer_length_cm": 40, "outer_width_cm": 30, "outer_height_cm": 25, "gross_weight_kg": 3.2, "empty_top_space_cm": 1.0, "trim_notice_yn": "N", "trim_possible_height_cm": null, "items": [ { "order_line_no": 1, "normalized_product_code": "AUTO_MATCH", "product_name": "비에녹스 200u", "product_type": "NORMAL", "packed_qty": 75, "fullbox_applied_yn": "N", "package_kept_yn": "N", "special_rule_applied_yn": "N" } ] } ], "manual_review_items": [], "packing_notes": [ "상단 유효공간 2cm 이상인 카톤은 제단 안내를 표시한다." ] }

Sheet rules_master
A1: 패킹 엔진 규칙 마스터
A3: rule_key | B3: rule_value | C3: rule_type | D3: 설명 | E3: source
A4: PACK_OBJECTIVE_PRIMARY | B4: MIN_BOX_COUNT | C4: enum | D4: 박스 수량 최소화가 최우선 | E4: 사용자합의
A5: PACK_SAME_PRODUCT_FIRST | B5: Y | C5: bool | D5: 같은 상품 우선 패킹 | E5: 사용자합의
A6: NORMAL_BOX_TIEBREAK | B6: LARGE_BOX_FIRST | C6: enum | D6: 일반 상품은 동일 박스 수량이면 큰 박스를 먼저 사용 | E6: 사용자합의
A7: SPECIAL_FAMILIES | B7: ELASTY|CELLOZOME|REPLENGEN|RICHESSE_C|DEMEI | C7: text | D7: 특수 상품군 코드 | E7: products_master.특수상품군
A8: SPECIAL_PRIORITY_BOX_CODE | B8: BX010 | C8: text | D8: 특수 상품군 우선 박스코드(72x48x40) | E8: 사용자합의
A9: SPECIAL_PRIORITY_UNITS | B9: 300 | C9: number | D9: 특수 상품군 우선 배정 수량 | E9: 사용자합의
A10: BOX_INNER_MARGIN_CM | B10: 1 | C10: number | D10: 계산용 내경 = 외경 - 1cm | E10: 사용자합의
A11: MAX_BOX_WEIGHT_KG | B11: 30 | C11: number | D11: 30kg 초과 금지 | E11: 사용자합의
A12: PACKAGE_AUTO_DETECT | B12: packages_master | C12: text | D12: 패키지 상품 자동 판별 기준 시트 | E12: 사용자합의
A13: TOP_EMPTY_SPACE_NOTICE_CM | B13: 2 | C13: number | D13: 상단 유효공간 2cm 이상이면 안내 | E13: 사용자합의
A14: OUTPUT_FORMAT | B14: PACKING_LIST_TEMPLATE | C14: text | D14: 패킹리스트는 템플릿 형식 기준 출력 | E14: 사용자합의
A15: FULLBOX_INTERPRETATION | B15: OWN_CARTON | C15: enum | D15: 완박스는 표준 박스로 매핑하지 않고 자체 출고 카톤으로 인정 | E15: 이번확정
A16: FULLBOX_STANDARD_BOX_MAPPING | B16: DISABLED | C16: enum | D16: 완박스 -> boxes_master 직접 매핑 비활성화 | E16: 이번확정
A17: FULLBOX_SEQUENCE | B17: FULLBOX_FIRST_THEN_REPACK_REMAINDER | C17: enum | D17: 완박스 출고를 먼저 배정하고 잔량만 재포장 | E17: 이번확정
A18: FULLBOX_CARTON_SOURCE | B18: fullboxes_master | C18: text | D18: 완박스 카톤 규격 원본 시트 | E18: 이번확정
A19: FULLBOX_MISSING_DIM_ACTION | B19: MANUAL_REVIEW | C19: enum | D19: 완박스 규격/중량 누락 행은 수동 검토 대상으로 분리 | E19: 이번확정
A20: PACKAGE_INTERPRETATION | B20: PACKAGE_AS_IS_FIRST | C20: enum | D20: 패키지 상품은 기본적으로 해체하지 않고 패키지 상태 그대로 계산 | E20: 이번확정
A21: PACKAGE_REPACK_UNIT | B21: PACKAGE_UNIT | C21: enum | D21: 패키지 재포장은 개별 구성품이 아니라 패키지 단위 기준으로 계산 | E21: 이번확정
A22: PACKAGE_UNPACK_DEFAULT | B22: DISALLOW | C22: enum | D22: 패키지 해체는 기본 비허용 | E22: 이번확정
A23: PACKAGE_UNPACK_ALLOWED_WHEN | B23: NEED_AND_BOM_EXISTS_AND_POLICY_ALLOWS | C23: enum | D23: BOM 존재 + 패키지해체정책 허용 + 실제 필요 시에만 해체 | E23: 이번확정
A24: PACKAGE_BOM_SOURCE | B24: package_bom_master | C24: text | D24: 패키지 해체 계산에 필요한 구성품(BOM) 기준 시트 | E24: 이번확정
A25: PACKAGE_NO_BOM_ACTION | B25: KEEP_SEALED_OR_MANUAL_REVIEW | C25: enum | D25: BOM이 없으면 패키지 상태 유지. 해체가 꼭 필요하면 수동 검토 | E25: 이번확정
... A31: FULLBOX_MIX_GROUP_FIRST | B31: Y | C31: bool | D31: 동일 혼합그룹 잔량을 우선 합포 | E31: 이번확정
A32: FULLBOX_MIX_TOL_LENGTH_CM | B32: 0.3 | C32: number | D32: 완박스 혼합 허용 가로 오차(cm) | E32: 이번확정
A33: FULLBOX_MIX_TOL_WIDTH_CM | B33: 0.3 | C33: number | D33: 완박스 혼합 허용 세로 오차(cm) | E33: 이번확정
A34: FULLBOX_MIX_TOL_HEIGHT_CM | B34: 0.3 | C34: number | D34: 완박스 혼합 허용 높이 오차(cm) | E34: 이번확정
A35: FULLBOX_MIX_TOL_WEIGHT_KG | B35: 0.005 | C35: number | D35: 완박스 혼합 허용 개당중량 오차(kg) | E35: 이번확정
A36: FULLBOX_REMAINDER_TO_REPACK | B36: Y | C36: bool | D36: 혼합 후 남는 잔량은 재포장으로 처리 | E36: 이번확정
A37: MATCH_FAIL_POLICY | B37: MATCH_FAILED | C37: enum | D37: 매칭 실패 시 수동검토 없이 실패 처리 | E37: 이번확정
A38: PRODUCT_NOT_FOUND_POLICY | B38: FAIL | C38: enum | D38: 상품이 마스터에 없으면 FAIL 처리 | E38: 이번확정
A39: BOX_MAX_WEIGHT_KG | B39: 30 | C39: number | D39: 최대 박스 중량(kg) | E39: 이번확정

Sheet engine_gap_review
A1: 계산 엔진 관점 점검 결과
A3: 우선순위 | B3: 시트명 | C3: 현재상태 | D3: 엔진 관점 갭 | E3: 권장 조치 | F3: 비고
A4: HIGH | B4: products_master | C4: 대체로 양호 | D4: 별칭/정규화명 없음. 그러나 패킹정책코드와 특수우선 컬럼은 이번 검토본에 추가함 | E4: 향후 alias_names / product_name_norm이 필요하면 별도 확장 | F4: 상품 462개
A5: HIGH | B5: boxes_master | C5: 양호 | D5: 엔진용 우선순위 컬럼이 없었음 | E5: 이번 검토본에 박스정렬우선순위 추가 | F5: 박스 10종
A6: HIGH | B6: fullboxes_master | C6: 부분적 준비 | D6: 표준 박스코드(box_id)가 없고, 현재 치수도 boxes_master와 직접 매핑되지 않음 | E6: 완박스 자체 규격인지 표준 박스 사용인지 정책 확정 필요 | F6: 완박스 178개
A7: MEDIUM | B7: packages_master | C7: 부분적 준비 | D7: 현재는 패키지 SKU 식별용으로 충분하나, 구성품 분해 계산이 필요하면 BOM 구조가 추가로 필요 | E7: 패키지를 원자 SKU로 볼지 구성품으로 풀지 정책 확정 | F7: 패키지 18개
A8: MEDIUM | B8: README | C8: 기본 안내 있음 | D8: 엔진 버전 이력과 스키마 정의가 없음 | E8: rules_master / engine_gap_review를 기준 문서로 사용 | F8: -
A9: HIGH | B9: fullboxes_master | C9: 정책 확정 | D9: 표준 박스와 직접 매핑 불가 | E9: 완박스를 OWN_CARTON으로 처리하고 잔량만 재포장 | F9: 고유 완박스카톤 92종 / 수동검토 1행
A10: HIGH | B10: packages_master | C10: 이번 확정으로 보완 | D10: 패키지 상태 우선/해체 조건/BOM 존재 여부가 명시되지 않았음 | E10: 이번 검토본에 엔진정책 컬럼 추가, 기본은 PACKAGE_AS_IS_FIRST로 고정 | F10: 패키지 18개
A11: HIGH | B11: package_bom_master | C11: 신규 템플릿 | D11: 현재 원본에는 패키지 구성품(BOM) 데이터가 없음 | E11: 해체 계산이 필요할 때만 이 시트에 패키지별 구성품 코드를 추가 | F11: 현재 데이터 0건
A12: HIGH | B12: engine_flow/output_schema | C12: 이번 확정으로 보완 | D12: 계산 순서와 출력 필드가 문서화되어 있지 않았음 | E12: engine_flow, output_schema 시트 추가로 입력→계산→출력 구조 고정 | F12: 구현 기준 시트
A13: HIGH | B13: input_json_schema/output_json_schema | C13: 이번 확정으로 보완 | D13: 요청/응답 JSON 구조가 문서화되어 있지 않았음 | E13: input_json_schema, output_json_schema, json_examples 시트 추가로 API 계약 고정 | F13: 구현/테스트 기준 시트
A14: HIGH | B14: fullboxes_master/products_master/rules_master | C14: 이번 확정으로 보완 | D14: 완박스 잔량 혼합 기준과 허용오차 정책이 문서/마스터에 반영되지 않았음 | E14: 혼합완박스허용여부, 완박스혼합그룹, 허용오차 규칙을 시트에 반영 | F14: FULLBOX 혼합정책 반영
